Workbook
Name WDI_RAW: Table2[#All]

Sheet Raw Data
A1: Country Name | B1: Country Code | C1: Series Name | D1: Series Code | E1: 2000 [YR2000] | F1: 2001 [YR2001] | G1: 2002 [YR2002] | H1: 2003 [YR2003] | I1: 2004 [YR2004] | J1: 2005 [YR2005] | K1: 2006 [YR2006] | L1: 2007 [YR2007] | M1: 2008 [YR2008] | N1: 2017 [YR2017] | O1: 2018 [YR2018] | P1: 2019 [YR2019] | Q1: 2020 [YR2020] | R1: 2021 [YR2021] | S1: 2022 [YR2022] | T1: 2023 [YR2023] | U1: 2024 [YR2024] | V1: 2025 [YR2025]
A2: Afghanistan | B2: AFG | C2: Broad money (% of GDP) | D2: FM.LBL.BMNY.GD.ZS | E2: .. | F2: .. | G2: .. | H2: .. | I2: .. | J2: .. | K2: 23.343865 | L2: 23.833664 | M2: 29.512281 | N2: 36.861261 | O2: 36.607494 | P2: 34.959214 | Q2: 37.508189 | R2: .. | S2: .. | T2: .. | U2: .. | V2: ..
A3: Afghanistan | B3: AFG | C3: Access to electricity, rural (% of rural population) | D3: EG.ELC.ACCS.RU.ZS | E3: .. | F3: .. | G3: .. | H3: 2.1 | I3: 7.8 | J3: 15.4 | K3: 19.3 | L3: 25 | M3: 28 | N3: 97.1 | O3: 91.6 | P3: 97.1 | Q3: 97.1 | R3: 97.1 | S3: 81.7 | T3: 81.4 | U3: .. | V3: ..
A4: Afghanistan | B4: AFG | C4: Inflation, consumer prices (annual %) | D4: FP.CPI.TOTL.ZG | E4: .. | F4: .. | G4: .. | H4: .. | I4: .. | J4: 12.686269 | K4: 6.7845966 | L4: 8.6805708 | M4: 26.418664 | N4: 4.9759515 | O4: 0.62614915 | P4: 2.3023725 | Q4: 5.6018879 | R4: 5.1332034 | S4: 13.712102 | T4: -4.6447087 | U4: -6.6011856 | V4: ..
A5: Afghanistan | B5: AFG | C5: Inflation, GDP deflator (annual %) | D5: NY.GDP.DEFL.KD.ZG | E5: .. | F5: -11.774536 | G5: 6.125522 | H5: 11.655238 | I5: 11.271432 | J5: 10.912774 | K5: 7.1997513 | L5: 22.527756 | M5: 2.0962888 | N5: 2.4036562 | O5: 2.0713486 | P5: 6.5214798 | Q5: 6.9629463 | R5: 2.8389963 | S5: 9.4062393 | T5: 2.9236621 | U5: .. | V5: ..
A6: Afghanistan | B6: AFG | C6: Trade in services (% of GDP) | D6: BG.GSR.NFSV.GD.ZS | E6: .. | F6: .. | G6: .. | H6: .. | I6: .. | J6: .. | K6: .. | L6: .. | M6: 20.211726 | N6: 8.5806823 | O6: 11.638305 | P6: 9.918134 | Q6: 9.0438455 | R6: .. | S6: .. | T6: .. | U6: .. | V6: ..
A7: Albania | B7: ALB | C7: Broad money (% of GDP) | D7: FM.LBL.BMNY.GD.ZS | E7: 63.559947 | F7: 67.466477 | G7: 64.380525 | H7: 63.296713 | I7: 66.17596 | J7: 69.648068 | K7: 74.242141 | L7: 75.362987 | M7: 73.333402 | N7: 80.23339 | O7: 76.114797 | P7: 77.022846 | Q7: 87.983312 | R7: 84.766385 | S7: 77.185728 | T7: 71.828751 | U7: 70.9046 | V7: ..
A8: Albania | B8: ALB | C8: Access to electricity, rural (% of rural population) | D8: EG.ELC.ACCS.RU.ZS | E8: 100 | F8: 100 | G8: 100 | H8: 100 | I8: 100 | J8: 100 | K8: 100 | L8: 100 | M8: 100 | N8: 99.7 | O8: 100 | P8: 100 | Q8: 100 | R8: 100 | S8: 100 | T8: 100 | U8: .. | V8: ..
A9: Albania | B9: ALB | C9: Inflation, consumer prices (annual %) | D9: FP.CPI.TOTL.ZG | E9: 0.050018136 | F9: 3.1075883 | G9: 7.7705258 | H9: 0.48400261 | I9: 2.2800192 | J9: 2.366582 | K9: 2.3707283 | L9: 2.9326825 | M9: 3.3208709 | N9: 1.9866613 | O9: 2.0280596 | P9: 1.4110908 | Q9: 1.6208866 | R9: 2.0414716 | S9: 6.7252027 | T9: 4.7583456 | U9: 2.2158738 | V9: ..
A10: Albania | B10: ALB | C10: Inflation, GDP deflator (annual %) | D10: NY.GDP.DEFL.KD.ZG | E10: 5.9195735 | F10: 3.7659453 | G10: 3.9038814 | H10: 4.9374926 | I10: 3.0953665 | J10: 3.1437051 | K10: 2.6847683 | L10: 5.1495678 | M10: 3.4986391 | N10: 2.7250692 | O10: 1.4532872 | P10: 1.0006329 | Q10: 0.041064999 | R10: 3.4442568 | S10: 9.8616099 | T10: 5.733907 | U10: 2.3531809 | V10: ..
A11: Albania | B11: ALB | C11: Trade in services (% of GDP) | D11: BG.GSR.NFSV.GD.ZS | E11: 24.789583 | F11: 24.458841 | G11: 25.962551 | H11: 26.693325 | I11: 29.103663 | J11: 32.089796 | K11: 35.181631 | L11: 36.241931 | M11: 38.528108 | N11: 39.667021 | O11: 38.560048 | P11: 39.790381 | Q11: 25.556111 | R11: 33.896916 | S11: 39.58999 | T11: 45.057723 | U11: 43.852188 | V11: ..
A12: Algeria | B12: DZA | C12: Broad money (% of GDP) | D12: FM.LBL.BMNY.GD.ZS | E12: 37.829725 | F12: 52.381764 | G12: 57.87508 | H12: 58.015964 | I12: 55.021864 | J12: 51.892561 | K12: 54.464995 | L12: 60.717363 | M12: 59.709446 | N12: 71.063395 | O12: 73.341678 | P12: 71.505472 | Q12: 84.871789 | R12: 79.826032 | S12: 71.665003 | T12: 72.243913 | U12: 73.4802 | V12: ..
A13: Algeria | B13: DZA | C13: Access to electricity, rural (% of rural population) | D13: EG.ELC.ACCS.RU.ZS | E13: 97.4 | F13: 97.4 | G13: 97.4 | H13: 97.4 | I13: 97.4 | J13: 97.4 | K13: 97.4 | L13: 97.4 | M13: 97.9 | N13: 98.6 | O13: 98.9 | P13: 98.7 | Q13: 99.1 | R13: 99.3 | S13: 99.3 | T13: 100 | U13: .. | V13: ..
A14: Algeria | B14: DZA | C14: Inflation, consumer prices (annual %) | D14: FP.CPI.TOTL.ZG | E14: 0.33916319 | F14: 4.2259883 | G14: 1.4183019 | H14: 4.268954 | I14: 3.9618003 | J14: 1.3824466 | K14: 2.3114992 | L14: 3.6789957 | M14: 4.8585906 | N14: 5.5911159 | O14: 4.2699902 | P14: 1.9517682 | Q14: 2.4151309 | R14: 7.2260631 | S14: 9.2655155 | T14: 9.3221738 | U14: 4.0461146 | V14: ..
A15: Algeria | B15: DZA | C15: Inflation, GDP deflator (annual %) | D15: NY.GDP.DEFL.KD.ZG | E15: 22.678009 | F15: 8.014363 | G15: 1.3728559 | H15: 8.9424622 | I15: 11.446504 | J15: 12.361593 | K15: 10.781184 | L15: 7.0955158 | M15: 15.117882 | N15: 4.9380073 | O15: 6.1646784 | P15: 0.88299283 | Q15: -4.7113839 | R15: 15.9326 | S15: 22.920306 | T15: 1.0015314 | U15: 3.3749774 | V15: ..
A16: Algeria | B16: DZA | C16: Trade in services (% of GDP) | D16: BG.GSR.NFSV.GD.ZS | E16: .. | F16: .. | G16: .. | H16: .. | I16: .. | J16: 6.8474839 | K16: 6.0129541 | L16: 6.7620351 | M16: 8.0772087 | N16: 7.5752446 | O16: 7.7450915 | P16: 6.8114722 | Q16: 6.3240803 | R16: 5.4285891 | S16: 5.0696726 | T16: 4.8733878 | U16: 4.9582377 | V16: ..
A17: American Samoa | B17: ASM | C17: Broad money (% of GDP) | D17: FM.LBL.BMNY.GD.ZS | E17: .. | F17: .. | G17: .. | H17: .. | I17: .. | J17: .. | K17: .. | L17: .. | M17: .. | N17: .. | O17: .. | P17: .. | Q17: .. | R17: .. | S17: .. | T17: .. | U17: .. | V17: ..
A18: American Samoa | B18: ASM | C18: Access to electricity, rural (% of rural population) | D18: EG.ELC.ACCS.RU.ZS | E18: .. | F18: .. | G18: .. | H18: .. | I18: .. | J18: .. | K18: .. | L18: .. | M18: .. | N18: .. | O18: .. | P18: .. | Q18: .. | R18: .. | S18: .. | T18: .. | U18: .. | V18: ..
A19: American Samoa | B19: ASM | C19: Inflation, consumer prices (annual %) | D19: FP.CPI.TOTL.ZG | E19: .. | F19: .. | G19: .. | H19: .. | I19: .. | J19: .. | K19: .. | L19: .. | M19: .. | N19: .. | O19: .. | P19: .. | Q19: .. | R19: .. | S19: .. | T19: .. | U19: .. | V19: ..
A20: American Samoa | B20: ASM | C20: Inflation, GDP deflator (annual %) | D20: NY.GDP.DEFL.KD.ZG | E20: .. | F20: .. | G20: .. | H20: 1.3650529 | I20: -3.2590746 | J20: -1.3655834 | K20: 2.8136752 | L20: 3.1606122 | M20: 11.059335 | N20: -1.9408901 | O20: 1.6953611 | P20: 1.7482893 | Q20: 6.7287807 | R20: 4.8425557 | S20: 14.152765 | T20: .. | U20: .. | V20: ..
A21: American Samoa | B21: ASM | C21: Trade in services (% of GDP) | D21: BG.GSR.NFSV.GD.ZS | E21: .. | F21: .. | G21: .. | H21: .. | I21: .. | J21: .. | K21: .. | L21: .. | M21: .. | N21: .. | O21: .. | P21: .. | Q21: .. | R21: .. | S21: .. | T21: .. | U21: .. | V21: ..
A22: Andorra | B22: AND | C22: Broad money (% of GDP) | D22: FM.LBL.BMNY.GD.ZS | E22: .. | F22: .. | G22: .. | H22: .. | I22: .. | J22: .. | K22: .. | L22: .. | M22: .. | N22: .. | O22: .. | P22: .. | Q22: .. | R22: .. | S22: .. | T22: .. | U22: .. | V22: ..
A23: Andorra | B23: AND | C23: Access to electricity, rural (% of rural population) | D23: EG.ELC.ACCS.RU.ZS | E23: 100 | F23: 100 | G23: 100 | H23: 100 | I23: 100 | J23: 100 | K23: 100 | L23: 100 | M23: 100 | N23: 100 | O23: 100 | P23: 100 | Q23: 100 | R23: 100 | S23: 100 | T23: 100 | U23: .. | V23: ..
A24: Andorra | B24: AND | C24: Inflation, consumer prices (annual %) | D24: FP.CPI.TOTL.ZG | E24: .. | F24: .. | G24: .. | H24: .. | I24: .. | J24: .. | K24: .. | L24: .. | M24: .. | N24: .. | O24: .. | P24: .. | Q24: .. | R24: .. | S24: .. | T24: .. | U24: .. | V24: ..
A25: Andorra | B25: AND | C25: Inflation, GDP deflator (annual %) | D25: NY.GDP.DEFL.KD.ZG | E25: 28.741553 | F25: 3.0805352 | G25: 3.2395318 | H25: 3.1774842 | I25: 3.042424 | J25: 3.3961021 | K25: 3.4571841 | L25: 3.2112273 | M25: 2.2743383 | N25: 1.1365093 | O25: 1.0124785 | P25: 1.3747535 | Q25: 1.1137861 | R25: 2.5588607 | S25: 4.2366523 | T25: 6.2956008 | U25: 3.1436554 | V25: ..
A26: Andorra | B26: AND | C26: Trade in services (% of GDP) | D26: BG.GSR.NFSV.GD.ZS | E26: .. | F26: .. | G26: .. | H26: .. | I26: .. | J26: .. | K26: .. | L26: .. | M26: .. | N26: .. | O26: .. | P26: 87.579553 | Q26: 75.315498 | R26: 87.495948 | S26: 94.434915 | T26: 99.506414 | U26: 109.27757 | V26: ..
A27: Angola | B27: AGO | C27: Broad money (% of GDP) | D27: FM.LBL.BMNY.GD.ZS | E27: 17.280556 | F27: 21.135714 | G27: 14.171608 | H27: 11.828681 | I27: 11.823712 | J27: 11.877928 | K27: 14.532997 | L27: 18.271273 | M27: 28.249531 | N27: 28.10993 | O27: 27.201483 | P27: 29.587702 | Q27: 33.022497 | R27: 21.619274 | S27: 17.31393 | T27: 19.973799 | U27: 16.112562 | V27: ..
A28: Angola | B28: AGO | C28: Access to electricity, rural (% of rural population) | D28: EG.ELC.ACCS.RU.ZS | E28: 3.5 | F28: 9.5 | G28: 2.8 | H28: 2.3 | I28: 1.7 | J28: 1 | K28: 0.7 | L28: .. | M28: 6.6 | N28: .. | O28: 7.3 | P28: .. | Q28: .. | R28: .. | S28: .. | T28: .. | U28: .. | V28: ..
A29: Angola | B29: AGO | C29: Inflation, consumer prices (annual %) | D29: FP.CPI.TOTL.ZG | E29: 324.99687 | F29: 152.56102 | G29: 108.89744 | H29: 98.224144 | I29: 43.542107 | J29: 22.953514 | K29: 13.30521 | L29: 12.251497 | M29: 12.475829 | N29: 29.84448 | O29: 19.628938 | P29: 17.080954 | Q29: 22.271539 | R29: 25.754295 | S29: 21.35529 | T29: 13.644102 | U29: 28.240495 | V29: ..
A30: Angola | B30: AGO | C30: Inflation, GDP deflator (annual %) | D30: NY.GDP.DEFL.KD.ZG | E30: 418.01899 | F30: 106.35213 | G30: 236.34574 | H30: 94.607261 | I30: 33.382324 | J30: 40.136451 | K30: 16.814418 | L30: 5.1745141 | M30: 19.427383 | N30: 23.712806 | O30: 25.194156 | P30: 19.865888 | Q30: 16.063581 | R30: 35.653692 | S30: 18.121772 | T30: 17.929233 | U30: 24.604584 | V30: ..
A31: Angola | B31: AGO | C31: Trade in services (% of GDP) | D31: BG.GSR.NFSV.GD.ZS | E31: 32.495965 | F31: 41.636046 | G31: 20.384059 | H31: 17.314894 | I31: 18.98474 | J31: 16.831823 | K31: 15.336499 | L31: 17.735958 | M31: 22.743898 | N31: 17.514116 | O31: 11.976649 | P31: 10.685468 | Q31: 9.6335065 | R31: 8.9792802 | S31: 8.6722768 | T31: 8.0983565 | U31: 8.5358912 | V31: ..
A32: Antigua and Barbuda | B32: ATG | C32: Broad money (% of GDP) | D32: FM.LBL.BMNY.GD.ZS | E32: 72.41106 | F32: 77.993139 | G32: 80.309875 | H32: 87.924802 | I32: 86.205501 | J32: 84.187929 | K32: 82.432029 | L32: 80.462846 | M32: 79.371188 | N32: 87.31163 | O32: 86.469038 | P32: 82.844155 | Q32: 92.484771 | R32: 92.787136 | S32: 83.302316 | T32: 80.109967 | U32: 76.142397 | V32: ..
A33: Antigua and Barbuda | B33: ATG | C33: Access to electricity, rural (% of rural population) | D33: EG.ELC.ACCS.RU.ZS | E33: 96.6 | F33: 96.7 | G33: 100 | H33: 97 | I33: 97.1 | J33: 100 | K33: 100 | L33: 100 | M33: 100 | N33: 100 | O33: 100 | P33: 100 | Q33: 100 | R33: 100 | S33: 100 | T33: 100 | U33: .. | V33: ..
A34: Antigua and Barbuda | B34: ATG | C34: Inflation, consumer prices (annual %) | D34: FP.CPI.TOTL.ZG | E34: 0.7717798 | F34: 1.4027966 | G34: 2.407658 | H34: 1.9935306 | I34: 2.0300776 | J34: 2.098752 | K34: 1.7877854 | L34: 1.4160526 | M34: 5.3338064 | N34: 2.4324879 | O34: 1.2071579 | P34: 1.431356 | Q34: 0.62598971 | R34: 2.0629964 | S34: 7.5310783 | T34: 5.0671387 | U34: 6.198867 | V34: ..
A35: Antigua and Barbuda | B35: ATG | C35: Inflation, GDP deflator (annual %) | D35: NY.GDP.DEFL.KD.ZG | E35: 1.5355154 | F35: 2.063778 | G35: 1.2744512 | H35: -0.47933004 | I35: 2.3486479 | J35: 4.6784983 | K35: 1.1176722 | L35: 4.3693205 | M35: 4.7383582 | N35: 0.31653179 | O35: 1.4442184 | P35: 0.71233504 | Q35: 0.78165357 | R35: 4.9192746 | S35: 6.7802747 | T35: 4.9119408 | U35: 6.1804095 | V35: ..
A36: Antigua and Barbuda | B36: ATG | C36: Trade in services (% of GDP) | D36: BG.GSR.NFSV.GD.ZS | E36: 91.233804 | F36: 93.789824 | G36: 95.669204 | H36: 100.42616 | I36: 102.10806 | J36: 98.060973 | K36: 90.729591 | L36: 80.34372 | M36: 88.065746 | N36: 93.064846 | O36: 90.467962 | P36: 98.392769 | Q36: 61.566428 | R36: 62.27681 | S36: 81.339268 | T36: 80.300848 | U36: 81.448729 | V36: ..
A37: Argentina | B37: ARG | C37: Broad money (% of GDP) | D37: FM.LBL.BMNY.GD.ZS | E37: 31.848621 | F37: 27.139252 | G37: 27.92707 | H37: 30.104057 | I37: 28.325646 | J37: 28.66331 | K37: 28.049612 | L37: 27.864316 | M37: 23.493673 | N37: 28.49528 | O37: 30.410756 | P37: 26.183039 | Q37: 34.505263 | R37: 30.730954 | S37: 32.191836 | T37: 35.821852 | U37: 26.333931 | V37: ..
A38: Argentina | B38: ARG | C38: Access to electricity, rural (% of rural population) | D38: EG.ELC.ACCS.RU.ZS | E38: 91.8 | F38: 88.6 | G38: 92.6 | H38: 92.9 | I38: 93.2 | J38: 93.4 | K38: 93.6 | L38: 93.8 | M38: 94 | N38: 100 | O38: 99.9 | P38: 100 | Q38: 100 | R38: 100 | S38: 100 | T38: 100 | U38: .. | V38: ..
A39: Argentina | B39: ARG | C39: Inflation, consumer prices (annual %) | D39: FP.CPI.TOTL.ZG | E39: .. | F39: .. | G39: .. | H39: .. | I39: .. | J39: .. | K39: .. | L39: .. | M39: .. | N39: .. | O39: 34.277224 | P39: 53.548304 | Q39: 42.015095 | R39: 48.409379 | S39: 72.430758 | T39: 133.48894 | U39: 219.88393 | V39: ..
A40: Argentina | B40: ARG | C40: Inflation, GDP deflator (annual %) | D40: NY.GDP.DEFL.KD.ZG | E40: 1.0372871 | F40: -1.0957677 | G40: 30.555204 | H40: 10.495703 | I40: 18.363354 | J40: 10.317511 | K40: 13.741052 | L40: 14.939925 | M40: 23.171165 | N40: 26.006379 | O40: 42.033669 | P40: 49.195579 | Q40: 40.083088 | R40: 53.802088 | S40: 68.993827 | T40: 136.74236 | U40: 207.60524 | V40: ..
...

Sheet Working
A1: Country Name | B1: Country Code | C1: Series Name | D1: Series Code | E1: 2000 | F1: 2001 | G1: 2002 | H1: 2003 | I1: 2004 | J1: 2005 | K1: 2006 | L1: 2007 | M1: 2008 | N1: 2017 | O1: 2018 | P1: 2019 | Q1: 2020 | R1: 2021 | S1: 2022 | T1: 2023 | U1: 2024
A2: Afghanistan | B2: AFG | C2: Broad money (% of GDP) | D2: FM.LBL.BMNY.GD.ZS | K2: 23.343865 | L2: 23.833664 | M2: 29.512281 | N2: 36.861261 | O2: 36.607494 | P2: 34.959214 | Q2: 37.508189
A3: Afghanistan | B3: AFG | C3: Access to electricity, rural (% of rural population) | D3: EG.ELC.ACCS.RU.ZS | H3: 2.1 | I3: 7.8 | J3: 15.4 | K3: 19.3 | L3: 25 | M3: 28 | N3: 97.1 | O3: 91.6 | P3: 97.1 | Q3: 97.1 | R3: 97.1 | S3: 81.7 | T3: 81.4
A4: Afghanistan | B4: AFG | C4: Inflation, consumer prices (annual %) | D4: FP.CPI.TOTL.ZG | J4: 12.686269 | K4: 6.7845966 | L4: 8.6805708 | M4: 26.418664 | N4: 4.9759515 | O4: 0.62614915 | P4: 2.3023725 | Q4: 5.6018879 | R4: 5.1332034 | S4: 13.712102 | T4: -4.6447087 | U4: -6.6011856
A5: Afghanistan | B5: AFG | C5: Inflation, GDP deflator (annual %) | D5: NY.GDP.DEFL.KD.ZG | F5: -11.774536 | G5: 6.125522 | H5: 11.655238 | I5: 11.271432 | J5: 10.912774 | K5: 7.1997513 | L5: 22.527756 | M5: 2.0962888 | N5: 2.4036562 | O5: 2.0713486 | P5: 6.5214798 | Q5: 6.9629463 | R5: 2.8389963 | S5: 9.4062393 | T5: 2.9236621
A6: Afghanistan | B6: AFG | C6: Trade in services (% of GDP) | D6: BG.GSR.NFSV.GD.ZS | M6: 20.211726 | N6: 8.5806823 | O6: 11.638305 | P6: 9.918134 | Q6: 9.0438455
A7: Albania | B7: ALB | C7: Broad money (% of GDP) | D7: FM.LBL.BMNY.GD.ZS | E7: 63.559947 | F7: 67.466477 | G7: 64.380525 | H7: 63.296713 | I7: 66.17596 | J7: 69.648068 | K7: 74.242141 | L7: 75.362987 | M7: 73.333402 | N7: 80.23339 | O7: 76.114797 | P7: 77.022846 | Q7: 87.983312 | R7: 84.766385 | S7: 77.185728 | T7: 71.828751 | U7: 70.9046
A8: Albania | B8: ALB | C8: Access to electricity, rural (% of rural population) | D8: EG.ELC.ACCS.RU.ZS | E8: 100 | F8: 100 | G8: 100 | H8: 100 | I8: 100 | J8: 100 | K8: 100 | L8: 100 | M8: 100 | N8: 99.7 | O8: 100 | P8: 100 | Q8: 100 | R8: 100 | S8: 100 | T8: 100
A9: Albania | B9: ALB | C9: Inflation, consumer prices (annual %) | D9: FP.CPI.TOTL.ZG | E9: 0.050018136 | F9: 3.1075883 | G9: 7.7705258 | H9: 0.48400261 | I9: 2.2800192 | J9: 2.366582 | K9: 2.3707283 | L9: 2.9326825 | M9: 3.3208709 | N9: 1.9866613 | O9: 2.0280596 | P9: 1.4110908 | Q9: 1.6208866 | R9: 2.0414716 | S9: 6.7252027 | T9: 4.7583456 | U9: 2.2158738
A10: Albania | B10: ALB | C10: Inflation, GDP deflator (annual %) | D10: NY.GDP.DEFL.KD.ZG | E10: 5.9195735 | F10: 3.7659453 | G10: 3.9038814 | H10: 4.9374926 | I10: 3.0953665 | J10: 3.1437051 | K10: 2.6847683 | L10: 5.1495678 | M10: 3.4986391 | N10: 2.7250692 | O10: 1.4532872 | P10: 1.0006329 | Q10: 0.041064999 | R10: 3.4442568 | S10: 9.8616099 | T10: 5.733907 | U10: 2.3531809
A11: Albania | B11: ALB | C11: Trade in services (% of GDP) | D11: BG.GSR.NFSV.GD.ZS | E11: 24.789583 | F11: 24.458841 | G11: 25.962551 | H11: 26.693325 | I11: 29.103663 | J11: 32.089796 | K11: 35.181631 | L11: 36.241931 | M11: 38.528108 | N11: 39.667021 | O11: 38.560048 | P11: 39.790381 | Q11: 25.556111 | R11: 33.896916 | S11: 39.58999 | T11: 45.057723 | U11: 43.852188
A12: Algeria | B12: DZA | C12: Broad money (% of GDP) | D12: FM.LBL.BMNY.GD.ZS | E12: 37.829725 | F12: 52.381764 | G12: 57.87508 | H12: 58.015964 | I12: 55.021864 | J12: 51.892561 | K12: 54.464995 | L12: 60.717363 | M12: 59.709446 | N12: 71.063395 | O12: 73.341678 | P12: 71.505472 | Q12: 84.871789 | R12: 79.826032 | S12: 71.665003 | T12: 72.243913 | U12: 73.4802
A13: Algeria | B13: DZA | C13: Access to electricity, rural (% of rural population) | D13: EG.ELC.ACCS.RU.ZS | E13: 97.4 | F13: 97.4 | G13: 97.4 | H13: 97.4 | I13: 97.4 | J13: 97.4 | K13: 97.4 | L13: 97.4 | M13: 97.9 | N13: 98.6 | O13: 98.9 | P13: 98.7 | Q13: 99.1 | R13: 99.3 | S13: 99.3 | T13: 100
A14: Algeria | B14: DZA | C14: Inflation, consumer prices (annual %) | D14: FP.CPI.TOTL.ZG | E14: 0.33916319 | F14: 4.2259883 | G14: 1.4183019 | H14: 4.268954 | I14: 3.9618003 | J14: 1.3824466 | K14: 2.3114992 | L14: 3.6789957 | M14: 4.8585906 | N14: 5.5911159 | O14: 4.2699902 | P14: 1.9517682 | Q14: 2.4151309 | R14: 7.2260631 | S14: 9.2655155 | T14: 9.3221738 | U14: 4.0461146
A15: Algeria | B15: DZA | C15: Inflation, GDP deflator (annual %) | D15: NY.GDP.DEFL.KD.ZG | E15: 22.678009 | F15: 8.014363 | G15: 1.3728559 | H15: 8.9424622 | I15: 11.446504 | J15: 12.361593 | K15: 10.781184 | L15: 7.0955158 | M15: 15.117882 | N15: 4.9380073 | O15: 6.1646784 | P15: 0.88299283 | Q15: -4.7113839 | R15: 15.9326 | S15: 22.920306 | T15: 1.0015314 | U15: 3.3749774
A16: Algeria | B16: DZA | C16: Trade in services (% of GDP) | D16: BG.GSR.NFSV.GD.ZS | J16: 6.8474839 | K16: 6.0129541 | L16: 6.7620351 | M16: 8.0772087 | N16: 7.5752446 | O16: 7.7450915 | P16: 6.8114722 | Q16: 6.3240803 | R16: 5.4285891 | S16: 5.0696726 | T16: 4.8733878 | U16: 4.9582377
A17: American Samoa | B17: ASM | C17: Broad money (% of GDP) | D17: FM.LBL.BMNY.GD.ZS
A18: American Samoa | B18: ASM | C18: Access to electricity, rural (% of rural population) | D18: EG.ELC.ACCS.RU.ZS
A19: American Samoa | B19: ASM | C19: Inflation, consumer prices (annual %) | D19: FP.CPI.TOTL.ZG
A20: American Samoa | B20: ASM | C20: Inflation, GDP deflator (annual %) | D20: NY.GDP.DEFL.KD.ZG | H20: 1.3650529 | I20: -3.2590746 | J20: -1.3655834 | K20: 2.8136752 | L20: 3.1606122 | M20: 11.059335 | N20: -1.9408901 | O20: 1.6953611 | P20: 1.7482893 | Q20: 6.7287807 | R20: 4.8425557 | S20: 14.152765
A21: American Samoa | B21: ASM | C21: Trade in services (% of GDP) | D21: BG.GSR.NFSV.GD.ZS
A22: Andorra | B22: AND | C22: Broad money (% of GDP) | D22: FM.LBL.BMNY.GD.ZS
A23: Andorra | B23: AND | C23: Access to electricity, rural (% of rural population) | D23: EG.ELC.ACCS.RU.ZS | E23: 100 | F23: 100 | G23: 100 | H23: 100 | I23: 100 | J23: 100 | K23: 100 | L23: 100 | M23: 100 | N23: 100 | O23: 100 | P23: 100 | Q23: 100 | R23: 100 | S23: 100 | T23: 100
A24: Andorra | B24: AND | C24: Inflation, consumer prices (annual %) | D24: FP.CPI.TOTL.ZG
A25: Andorra | B25: AND | C25: Inflation, GDP deflator (annual %) | D25: NY.GDP.DEFL.KD.ZG | E25: 28.741553 | F25: 3.0805352 | G25: 3.2395318 | H25: 3.1774842 | I25: 3.042424 | J25: 3.3961021 | K25: 3.4571841 | L25: 3.2112273 | M25: 2.2743383 | N25: 1.1365093 | O25: 1.0124785 | P25: 1.3747535 | Q25: 1.1137861 | R25: 2.5588607 | S25: 4.2366523 | T25: 6.2956008 | U25: 3.1436554
A26: Andorra | B26: AND | C26: Trade in services (% of GDP) | D26: BG.GSR.NFSV.GD.ZS | P26: 87.579553 | Q26: 75.315498 | R26: 87.495948 | S26: 94.434915 | T26: 99.506414 | U26: 109.27757
A27: Angola | B27: AGO | C27: Broad money (% of GDP) | D27: FM.LBL.BMNY.GD.ZS | E27: 17.280556 | F27: 21.135714 | G27: 14.171608 | H27: 11.828681 | I27: 11.823712 | J27: 11.877928 | K27: 14.532997 | L27: 18.271273 | M27: 28.249531 | N27: 28.10993 | O27: 27.201483 | P27: 29.587702 | Q27: 33.022497 | R27: 21.619274 | S27: 17.31393 | T27: 19.973799 | U27: 16.112562
A28: Angola | B28: AGO | C28: Access to electricity, rural (% of rural population) | D28: EG.ELC.ACCS.RU.ZS | E28: 3.5 | F28: 9.5 | G28: 2.8 | H28: 2.3 | I28: 1.7 | J28: 1 | K28: 0.7 | M28: 6.6 | O28: 7.3
A29: Angola | B29: AGO | C29: Inflation, consumer prices (annual %) | D29: FP.CPI.TOTL.ZG | E29: 324.99687 | F29: 152.56102 | G29: 108.89744 | H29: 98.224144 | I29: 43.542107 | J29: 22.953514 | K29: 13.30521 | L29: 12.251497 | M29: 12.475829 | N29: 29.84448 | O29: 19.628938 | P29: 17.080954 | Q29: 22.271539 | R29: 25.754295 | S29: 21.35529 | T29: 13.644102 | U29: 28.240495
A30: Angola | B30: AGO | C30: Inflation, GDP deflator (annual %) | D30: NY.GDP.DEFL.KD.ZG | E30: 418.01899 | F30: 106.35213 | G30: 236.34574 | H30: 94.607261 | I30: 33.382324 | J30: 40.136451 | K30: 16.814418 | L30: 5.1745141 | M30: 19.427383 | N30: 23.712806 | O30: 25.194156 | P30: 19.865888 | Q30: 16.063581 | R30: 35.653692 | S30: 18.121772 | T30: 17.929233 | U30: 24.604584
A31: Angola | B31: AGO | C31: Trade in services (% of GDP) | D31: BG.GSR.NFSV.GD.ZS | E31: 32.495965 | F31: 41.636046 | G31: 20.384059 | H31: 17.314894 | I31: 18.98474 | J31: 16.831823 | K31: 15.336499 | L31: 17.735958 | M31: 22.743898 | N31: 17.514116 | O31: 11.976649 | P31: 10.685468 | Q31: 9.6335065 | R31: 8.9792802 | S31: 8.6722768 | T31: 8.0983565 | U31: 8.5358912
A32: Antigua and Barbuda | B32: ATG | C32: Broad money (% of GDP) | D32: FM.LBL.BMNY.GD.ZS | E32: 72.41106 | F32: 77.993139 | G32: 80.309875 | H32: 87.924802 | I32: 86.205501 | J32: 84.187929 | K32: 82.432029 | L32: 80.462846 | M32: 79.371188 | N32: 87.31163 | O32: 86.469038 | P32: 82.844155 | Q32: 92.484771 | R32: 92.787136 | S32: 83.302316 | T32: 80.109967 | U32: 76.142397
A33: Antigua and Barbuda | B33: ATG | C33: Access to electricity, rural (% of rural population) | D33: EG.ELC.ACCS.RU.ZS | E33: 96.6 | F33: 96.7 | G33: 100 | H33: 97 | I33: 97.1 | J33: 100 | K33: 100 | L33: 100 | M33: 100 | N33: 100 | O33: 100 | P33: 100 | Q33: 100 | R33: 100 | S33: 100 | T33: 100
A34: Antigua and Barbuda | B34: ATG | C34: Inflation, consumer prices (annual %) | D34: FP.CPI.TOTL.ZG | E34: 0.7717798 | F34: 1.4027966 | G34: 2.407658 | H34: 1.9935306 | I34: 2.0300776 | J34: 2.098752 | K34: 1.7877854 | L34: 1.4160526 | M34: 5.3338064 | N34: 2.4324879 | O34: 1.2071579 | P34: 1.431356 | Q34: 0.62598971 | R34: 2.0629964 | S34: 7.5310783 | T34: 5.0671387 | U34: 6.198867
A35: Antigua and Barbuda | B35: ATG | C35: Inflation, GDP deflator (annual %) | D35: NY.GDP.DEFL.KD.ZG | E35: 1.5355154 | F35: 2.063778 | G35: 1.2744512 | H35: -0.47933004 | I35: 2.3486479 | J35: 4.6784983 | K35: 1.1176722 | L35: 4.3693205 | M35: 4.7383582 | N35: 0.31653179 | O35: 1.4442184 | P35: 0.71233504 | Q35: 0.78165357 | R35: 4.9192746 | S35: 6.7802747 | T35: 4.9119408 | U35: 6.1804095
A36: Antigua and Barbuda | B36: ATG | C36: Trade in services (% of GDP) | D36: BG.GSR.NFSV.GD.ZS | E36: 91.233804 | F36: 93.789824 | G36: 95.669204 | H36: 100.42616 | I36: 102.10806 | J36: 98.060973 | K36: 90.729591 | L36: 80.34372 | M36: 88.065746 | N36: 93.064846 | O36: 90.467962 | P36: 98.392769 | Q36: 61.566428 | R36: 62.27681 | S36: 81.339268 | T36: 80.300848 | U36: 81.448729
A37: Argentina | B37: ARG | C37: Broad money (% of GDP) | D37: FM.LBL.BMNY.GD.ZS | E37: 31.848621 | F37: 27.139252 | G37: 27.92707 | H37: 30.104057 | I37: 28.325646 | J37: 28.66331 | K37: 28.049612 | L37: 27.864316 | M37: 23.493673 | N37: 28.49528 | O37: 30.410756 | P37: 26.183039 | Q37: 34.505263 | R37: 30.730954 | S37: 32.191836 | T37: 35.821852 | U37: 26.333931
A38: Argentina | B38: ARG | C38: Access to electricity, rural (% of rural population) | D38: EG.ELC.ACCS.RU.ZS | E38: 91.8 | F38: 88.6 | G38: 92.6 | H38: 92.9 | I38: 93.2 | J38: 93.4 | K38: 93.6 | L38: 93.8 | M38: 94 | N38: 100 | O38: 99.9 | P38: 100 | Q38: 100 | R38: 100 | S38: 100 | T38: 100
A39: Argentina | B39: ARG | C39: Inflation, consumer prices (annual %) | D39: FP.CPI.TOTL.ZG | O39: 34.277224 | P39: 53.548304 | Q39: 42.015095 | R39: 48.409379 | S39: 72.430758 | T39: 133.48894 | U39: 219.88393
A40: Argentina | B40: ARG | C40: Inflation, GDP deflator (annual %) | D40: NY.GDP.DEFL.KD.ZG | E40: 1.0372871 | F40: -1.0957677 | G40: 30.555204 | H40: 10.495703 | I40: 18.363354 | J40: 10.317511 | K40: 13.741052 | L40: 14.939925 | M40: 23.171165 | N40: 26.006379 | O40: 42.033669 | P40: 49.195579 | Q40: 40.083088 | R40: 53.802088 | S40: 68.993827 | T40: 136.74236 | U40: 207.60524
...

Sheet Long Format
A1: Country Name | B1: Country Code | C1: Series Name | D1: Series Code | E1: Year | F1: Value | G1: Gap Year
A2: Afghanistan | B2: AFG | C2: Broad money (% of GDP) | D2: FM.LBL.BMNY.GD.ZS | E2: 2006 | F2: 23.343865 | G2: No
A3: Afghanistan | B3: AFG | C3: Broad money (% of GDP) | D3: FM.LBL.BMNY.GD.ZS | E3: 2007 | F3: 23.833664 | G3: No
A4: Afghanistan | B4: AFG | C4: Broad money (% of GDP) | D4: FM.LBL.BMNY.GD.ZS | E4: 2008 | F4: 29.512281 | G4: No
A5: Afghanistan | B5: AFG | C5: Broad money (% of GDP) | D5: FM.LBL.BMNY.GD.ZS | E5: 2017 | F5: 36.861261 | G5: No
A6: Afghanistan | B6: AFG | C6: Broad money (% of GDP) | D6: FM.LBL.BMNY.GD.ZS | E6: 2018 | F6: 36.607494 | G6: No
A7: Afghanistan | B7: AFG | C7: Broad money (% of GDP) | D7: FM.LBL.BMNY.GD.ZS | E7: 2019 | F7: 34.959214 | G7: No
A8: Afghanistan | B8: AFG | C8: Broad money (% of GDP) | D8: FM.LBL.BMNY.GD.ZS | E8: 2020 | F8: 37.508189 | G8: No
A9: Afghanistan | B9: AFG | C9: Access to electricity, rural (% of rural population) | D9: EG.ELC.ACCS.RU.ZS | E9: 2003 | F9: 2.1 | G9: No
A10: Afghanistan | B10: AFG | C10: Access to electricity, rural (% of rural population) | D10: EG.ELC.ACCS.RU.ZS | E10: 2004 | F10: 7.8 | G10: No
A11: Afghanistan | B11: AFG | C11: Access to electricity, rural (% of rural population) | D11: EG.ELC.ACCS.RU.ZS | E11: 2005 | F11: 15.4 | G11: No
A12: Afghanistan | B12: AFG | C12: Access to electricity, rural (% of rural population) | D12: EG.ELC.ACCS.RU.ZS | E12: 2006 | F12: 19.3 | G12: No
A13: Afghanistan | B13: AFG | C13: Access to electricity, rural (% of rural population) | D13: EG.ELC.ACCS.RU.ZS | E13: 2007 | F13: 25 | G13: No
... A18253: World | B18253: WLD | C18253: Trade in services (% of GDP) | D18253: BG.GSR.NFSV.GD.ZS | E18253: 2024 | F18253: 15.237207 | G18253: No

Sheet Pivot Lab
A3: Average of Value | D3: Series Name
A4: Country Name | B4: Country Code | C4: Year | D4: Access to electricity, rural (% of rural population) | E4: Broad money (% of GDP) | F4: Inflation, consumer prices (annual %) | G4: Inflation, GDP deflator (annual %) | H4: Trade in services (% of GDP)
A5: Afghanistan | B5: AFG | C5: 2001 | G5: -11.774536
A6: Afghanistan | B6: AFG | C6: 2002 | G6: 6.125522
A7: Afghanistan | B7: AFG | C7: 2003 | D7: 2.1 | G7: 11.655238
A8: Afghanistan | B8: AFG | C8: 2004 | D8: 7.8 | G8: 11.271432
A9: Afghanistan | B9: AFG | C9: 2005 | D9: 15.4 | F9: 12.686269 | G9: 10.912774
A10: Afghanistan | B10: AFG | C10: 2006 | D10: 19.3 | E10: 23.343865 | F10: 6.7845966 | G10: 7.1997513
A11: Afghanistan | B11: AFG | C11: 2007 | D11: 25 | E11: 23.833664 | F11: 8.6805708 | G11: 22.527756
A12: Afghanistan | B12: AFG | C12: 2008 | D12: 28 | E12: 29.512281 | F12: 26.418664 | G12: 2.0962888 | H12: 20.211726
A13: Afghanistan | B13: AFG | C13: 2017 | D13: 97.1 | E13: 36.861261 | F13: 4.9759515 | G13: 2.4036562 | H13: 8.5806823
A14: Afghanistan | B14: AFG | C14: 2018 | D14: 91.6 | E14: 36.607494 | F14: 0.62614915 | G14: 2.0713486 | H14: 11.638305
A15: Afghanistan | B15: AFG | C15: 2019 | D15: 97.1 | E15: 34.959214 | F15: 2.3023725 | G15: 6.5214798 | H15: 9.918134
A16: Afghanistan | B16: AFG | C16: 2020 | D16: 97.1 | E16: 37.508189 | F16: 5.6018879 | G16: 6.9629463 | H16: 9.0438455
A17: Afghanistan | B17: AFG | C17: 2021 | D17: 97.1 | F17: 5.1332034 | G17: 2.8389963
A18: Afghanistan | B18: AFG | C18: 2022 | D18: 81.7 | F18: 13.712102 | G18: 9.4062393
A19: Afghanistan | B19: AFG | C19: 2023 | D19: 81.4 | F19: -4.6447087 | G19: 2.9236621
A20: Afghanistan | B20: AFG | C20: 2024 | F20: -6.6011856
A21: Africa Eastern and Southern | B21: AFE | C21: 2000 | D21: 8.6726535 | E21: 35.852469 | F21: 8.6014851 | G21: 11.117306 | H21: 10.502052
A22: Africa Eastern and Southern | B22: AFE | C22: 2001 | E22: 39.613793 | F22: 5.840354 | G22: 8.2433867 | H22: 11.24503
A23: Africa Eastern and Southern | B23: AFE | C23: 2002 | E23: 41.11137 | F23: 8.7637552 | G23: 9.1024145 | H23: 11.247821
A24: Africa Eastern and Southern | B24: AFE | C24: 2003 | D24: 9.7928108 | E24: 42.344633 | F24: 7.4497001 | G24: 7.8067409 | H24: 10.552602
A25: Africa Eastern and Southern | B25: AFE | C25: 2004 | D25: 10.890979 | E25: 43.032826 | F25: 5.0234207 | G25: 9.6003926 | H25: 10.505725
A26: Africa Eastern and Southern | B26: AFE | C26: 2005 | D26: 10.336474 | E26: 44.783676 | F26: 8.558038 | G26: 7.6236894 | H26: 10.722308
A27: Africa Eastern and Southern | B27: AFE | C27: 2006 | D27: 12.420047 | E27: 46.481186 | F27: 8.8981638 | G27: 7.6522543 | H27: 10.986198
A28: Africa Eastern and Southern | B28: AFE | C28: 2007 | D28: 12.364996 | E28: 48.717492 | F28: 8.4507748 | G28: 8.2457648 | H28: 11.714061
A29: Africa Eastern and Southern | B29: AFE | C29: 2008 | D29: 12.798477 | E29: 48.197285 | F29: 12.566645 | G29: 10.961412 | H29: 12.884239
A30: Africa Eastern and Southern | B30: AFE | C30: 2017 | D30: 25.375037 | E30: 44.865327 | F30: 6.2213753 | G30: 6.0750721 | H30: 10.824878
A31: Africa Eastern and Southern | B31: AFE | C31: 2018 | D31: 26.941984 | E31: 45.918925 | F31: 4.6898065 | G31: 4.3217587 | H31: 11.04845
A32: Africa Eastern and Southern | B32: AFE | C32: 2019 | D32: 28.983183 | E32: 46.33906 | F32: 4.1028508 | G32: 4.383673 | H32: 10.59159
A33: Africa Eastern and Southern | B33: AFE | C33: 2020 | D33: 30.909991 | E33: 50.315016 | F33: 5.1916294 | G33: 5.3752898 | H33: 8.3974362
A34: Africa Eastern and Southern | B34: AFE | C34: 2021 | D34: 32.709837 | E34: 48.316851 | F34: 6.8247271 | G34: 6.0881528 | H34: 8.3467495
A35: Africa Eastern and Southern | B35: AFE | C35: 2022 | D35: 33.747222 | E35: 46.410375 | F35: 10.883478 | G35: 9.0101345 | H35: 10.061505
A36: Africa Eastern and Southern | B36: AFE | C36: 2023 | D36: 35.240236 | E36: 47.987303 | F36: 7.3991856 | G36: 6.9213224 | H36: 10.879188
A37: Africa Eastern and Southern | B37: AFE | C37: 2024 | E37: 50.985869 | F37: 4.7708573 | G37: 6.077633 | H37: 10.83876
A38: Africa Western and Central | B38: AFW | C38: 2000 | D38: 16.389701 | E38: 15.195094 | F38: 2.5307752 | G38: 4.8154303 | H38: 10.761256
A39: Africa Western and Central | B39: AFW | C39: 2001 | D39: 15.831088 | E39: 111.93751 | F39: 4.3615291 | G39: 3.8617952 | H39: 11.657488
A40: Africa Western and Central | B40: AFW | C40: 2002 | D40: 15.314665 | E40: 113.34484 | F40: 3.1886933 | G40: 2.6733974 | H40: 10.67022
A41: Africa Western and Central | B41: AFW | C41: 2003 | D41: 20.585835 | E41: 107.4034 | F41: 1.7609041 | G41: 1.7188216 | H41: 10.752991
A42: Africa Western and Central | B42: AFW | C42: 2004 | D42: 16.824447 | E42: 92.25633 | F42: 0.69433631 | G42: 5.7241523 | H42: 9.9421539
...

Sheet Wide Format
A1: Country Name | B1: Country Code | C1: Year | D1: Rural electricity | E1: Broad money | F1: Inflation CPI | G1: Inflation deflator | H1: Trade services
A2: Afghanistan | B2: AFG | C2: 2001 | G2: -11.774536
A3: Afghanistan | B3: AFG | C3: 2002 | G3: 6.125522
A4: Afghanistan | B4: AFG | C4: 2003 | D4: 2.1 | G4: 11.655238
A5: Afghanistan | B5: AFG | C5: 2004 | D5: 7.8 | G5: 11.271432
A6: Afghanistan | B6: AFG | C6: 2005 | D6: 15.4 | F6: 12.686269 | G6: 10.912774
A7: Afghanistan | B7: AFG | C7: 2006 | D7: 19.3 | E7: 23.343865 | F7: 6.7845966 | G7: 7.1997513
A8: Afghanistan | B8: AFG | C8: 2007 | D8: 25 | E8: 23.833664 | F8: 8.6805708 | G8: 22.527756
A9: Afghanistan | B9: AFG | C9: 2008 | D9: 28 | E9: 29.512281 | F9: 26.418664 | G9: 2.0962888 | H9: 20.211726
A10: Afghanistan | B10: AFG | C10: 2017 | D10: 97.1 | E10: 36.861261 | F10: 4.9759515 | G10: 2.4036562 | H10: 8.5806823
A11: Afghanistan | B11: AFG | C11: 2018 | D11: 91.6 | E11: 36.607494 | F11: 0.62614915 | G11: 2.0713486 | H11: 11.638305
A12: Afghanistan | B12: AFG | C12: 2019 | D12: 97.1 | E12: 34.959214 | F12: 2.3023725 | G12: 6.5214798 | H12: 9.918134
A13: Afghanistan | B13: AFG | C13: 2020 | D13: 97.1 | E13: 37.508189 | F13: 5.6018879 | G13: 6.9629463 | H13: 9.0438455
A14: Afghanistan | B14: AFG | C14: 2021 | D14: 97.1 | F14: 5.1332034 | G14: 2.8389963
A15: Afghanistan | B15: AFG | C15: 2022 | D15: 81.7 | F15: 13.712102 | G15: 9.4062393
A16: Afghanistan | B16: AFG | C16: 2023 | D16: 81.4 | F16: -4.6447087 | G16: 2.9236621
A17: Afghanistan | B17: AFG | C17: 2024 | F17: -6.6011856
A18: Africa Eastern and Southern | B18: AFE | C18: 2000 | D18: 8.6726535 | E18: 35.852469 | F18: 8.6014851 | G18: 11.117306 | H18: 10.502052
A19: Africa Eastern and Southern | B19: AFE | C19: 2001 | E19: 39.613793 | F19: 5.840354 | G19: 8.2433867 | H19: 11.24503
A20: Africa Eastern and Southern | B20: AFE | C20: 2002 | E20: 41.11137 | F20: 8.7637552 | G20: 9.1024145 | H20: 11.247821
A21: Africa Eastern and Southern | B21: AFE | C21: 2003 | D21: 9.7928108 | E21: 42.344633 | F21: 7.4497001 | G21: 7.8067409 | H21: 10.552602
A22: Africa Eastern and Southern | B22: AFE | C22: 2004 | D22: 10.890979 | E22: 43.032826 | F22: 5.0234207 | G22: 9.6003926 | H22: 10.505725
A23: Africa Eastern and Southern | B23: AFE | C23: 2005 | D23: 10.336474 | E23: 44.783676 | F23: 8.558038 | G23: 7.6236894 | H23: 10.722308
A24: Africa Eastern and Southern | B24: AFE | C24: 2006 | D24: 12.420047 | E24: 46.481186 | F24: 8.8981638 | G24: 7.6522543 | H24: 10.986198
A25: Africa Eastern and Southern | B25: AFE | C25: 2007 | D25: 12.364996 | E25: 48.717492 | F25: 8.4507748 | G25: 8.2457648 | H25: 11.714061
A26: Africa Eastern and Southern | B26: AFE | C26: 2008 | D26: 12.798477 | E26: 48.197285 | F26: 12.566645 | G26: 10.961412 | H26: 12.884239
A27: Africa Eastern and Southern | B27: AFE | C27: 2017 | D27: 25.375037 | E27: 44.865327 | F27: 6.2213753 | G27: 6.0750721 | H27: 10.824878
A28: Africa Eastern and Southern | B28: AFE | C28: 2018 | D28: 26.941984 | E28: 45.918925 | F28: 4.6898065 | G28: 4.3217587 | H28: 11.04845
A29: Africa Eastern and Southern | B29: AFE | C29: 2019 | D29: 28.983183 | E29: 46.33906 | F29: 4.1028508 | G29: 4.383673 | H29: 10.59159
A30: Africa Eastern and Southern | B30: AFE | C30: 2020 | D30: 30.909991 | E30: 50.315016 | F30: 5.1916294 | G30: 5.3752898 | H30: 8.3974362
A31: Africa Eastern and Southern | B31: AFE | C31: 2021 | D31: 32.709837 | E31: 48.316851 | F31: 6.8247271 | G31: 6.0881528 | H31: 8.3467495
A32: Africa Eastern and Southern | B32: AFE | C32: 2022 | D32: 33.747222 | E32: 46.410375 | F32: 10.883478 | G32: 9.0101345 | H32: 10.061505
A33: Africa Eastern and Southern | B33: AFE | C33: 2023 | D33: 35.240236 | E33: 47.987303 | F33: 7.3991856 | G33: 6.9213224 | H33: 10.879188
A34: Africa Eastern and Southern | B34: AFE | C34: 2024 | E34: 50.985869 | F34: 4.7708573 | G34: 6.077633 | H34: 10.83876
A35: Africa Western and Central | B35: AFW | C35: 2000 | D35: 16.389701 | E35: 15.195094 | F35: 2.5307752 | G35: 4.8154303 | H35: 10.761256
A36: Africa Western and Central | B36: AFW | C36: 2001 | D36: 15.831088 | E36: 111.93751 | F36: 4.3615291 | G36: 3.8617952 | H36: 11.657488
A37: Africa Western and Central | B37: AFW | C37: 2002 | D37: 15.314665 | E37: 113.34484 | F37: 3.1886933 | G37: 2.6733974 | H37: 10.67022
A38: Africa Western and Central | B38: AFW | C38: 2003 | D38: 20.585835 | E38: 107.4034 | F38: 1.7609041 | G38: 1.7188216 | H38: 10.752991
A39: Africa Western and Central | B39: AFW | C39: 2004 | D39: 16.824447 | E39: 92.25633 | F39: 0.69433631 | G39: 5.7241523 | H39: 9.9421539
A40: Africa Western and Central | B40: AFW | C40: 2005 | D40: 17.069797 | E40: 90.86939 | F40: 5.6316335 | G40: 7.2305211 | H40: 8.68849
...

Sheet Correlation Matrix
B1: Rural electricity | C1: Broad money | D1: Inflation CPI | E1: Inflation deflator | F1: Trade services
A2: Rural electricity | B2: =CORREL('Wide Format'!D2:D4432,'Wide Format'!D2:D4432) -> 1 | C2: =CORREL('Wide Format'!E2:E4432,'Wide Format'!D2:D4432) -> 0.031387031 | D2: =CORREL('Wide Format'!F2:F4432,'Wide Format'!D2:D4432) -> -0.10841764 | E2: =CORREL('Wide Format'!G2:G4432,'Wide Format'!D2:D4432) -> 0.011959459 | F2: =CORREL('Wide Format'!H2:H4432,'Wide Format'!D2:D4432) -> 0.22533959
A3: Broad money | B3: =CORREL('Wide Format'!D2:D4432,'Wide Format'!E2:E4432) -> 0.031387031 | C3: =CORREL('Wide Format'!E2:E4432,'Wide Format'!E2:E4432) -> 1 | D3: =CORREL('Wide Format'!F2:F4432,'Wide Format'!E2:E4432) -> -0.021993382 | E3: =CORREL('Wide Format'!G2:G4432,'Wide Format'!E2:E4432) -> 0.010764517 | F3: =CORREL('Wide Format'!H2:H4432,'Wide Format'!E2:E4432) -> -0.020127612
A4: Inflation CPI | B4: =CORREL('Wide Format'!D2:D4432,'Wide Format'!F2:F4432) -> -0.10841764 | C4: =CORREL('Wide Format'!E2:E4432,'Wide Format'!F2:F4432) -> -0.021993382 | D4: =CORREL('Wide Format'!F2:F4432,'Wide Format'!F2:F4432) -> 1 | E4: =CORREL('Wide Format'!G2:G4432,'Wide Format'!F2:F4432) -> 0.69869289 | F4: =CORREL('Wide Format'!H2:H4432,'Wide Format'!F2:F4432) -> -0.069494584
A5: Inflation deflator | B5: =CORREL('Wide Format'!D2:D4432,'Wide Format'!G2:G4432) -> 0.011959459 | C5: =CORREL('Wide Format'!E2:E4432,'Wide Format'!G2:G4432) -> 0.010764517 | D5: =CORREL('Wide Format'!F2:F4432,'Wide Format'!G2:G4432) -> 0.69869289 | E5: =CORREL('Wide Format'!G2:G4432,'Wide Format'!G2:G4432) -> 1 | F5: =CORREL('Wide Format'!H2:H4432,'Wide Format'!G2:G4432) -> -0.064449334
A6: Trade services | B6: =CORREL('Wide Format'!D2:D4432,'Wide Format'!H2:H4432) -> 0.22533959 | C6: =CORREL('Wide Format'!E2:E4432,'Wide Format'!H2:H4432) -> -0.020127612 | D6: =CORREL('Wide Format'!F2:F4432,'Wide Format'!H2:H4432) -> -0.069494584 | E6: =CORREL('Wide Format'!G2:G4432,'Wide Format'!H2:H4432) -> -0.064449334 | F6: =CORREL('Wide Format'!H2:H4432,'Wide Format'!H2:H4432) -> 1

Sheet Country Rankings
A1: Country Name | B1: Country Code | C1: Avg Rural Electricity | D1: Rank | E1: Tier | F1: Avg Trade Services | G1: Trade Services Rank | H1: Trade Services Tier
A2: Luxembourg | B2: =VLOOKUP(A2,'Wide Format'!A:B,2,0) -> LUX | C2: =IFERROR(AVERAGEIFS('Long Format'!F147:F18398,'Long Format'!A147:A18398,A2,'Long Format'!C147:C18398,"Access to electricity, rural (% of rural population)"),"No Data") -> 100 | D2: =IFERROR(RANK(C2,C$2:C$257,0),"") -> 1 | E2: =IF(C2="No Data","No Data",IF(C2>=75,"High",IF(C2>=50,"Medium",IF(C2>=25,"Low","Very Low")))) -> High | F2: =IFERROR(AVERAGEIFS('Long Format'!F41:F18292,'Long Format'!A41:A18292,A2,'Long Format'!C41:C18292,"Trade in services (% of GDP)"),"No Data") -> 234.64078 | G2: =IFERROR(RANK(F2,F$2:F$257,0),"") -> 1 | H2: =IF(F2="No Data","No Data",IF(F2>=50,"High",IF(F2>=25,"Medium",IF(F2>=10,"Low","Very Low")))) -> High
A3: Malta | B3: =VLOOKUP(A3,'Wide Format'!A:B,2,0) -> MLT | C3: =IFERROR(AVERAGEIFS('Long Format'!F154:F18405,'Long Format'!A154:A18405,A3,'Long Format'!C154:C18405,"Access to electricity, rural (% of rural population)"),"No Data") -> 100 | D3: =IFERROR(RANK(C3,C$2:C$257,0),"") -> 1 | E3: =IF(C3="No Data","No Data",IF(C3>=75,"High",IF(C3>=50,"Medium",IF(C3>=25,"Low","Very Low")))) -> High | F3: =IFERROR(AVERAGEIFS('Long Format'!F43:F18294,'Long Format'!A43:A18294,A3,'Long Format'!C43:C18294,"Trade in services (% of GDP)"),"No Data") -> 133.25236 | G3: =IFERROR(RANK(F3,F$2:F$257,0),"") -> 2 | H3: =IF(F3="No Data","No Data",IF(F3>=50,"High",IF(F3>=25,"Medium",IF(F3>=10,"Low","Very Low")))) -> High
A4: Ireland | B4: =VLOOKUP(A4,'Wide Format'!A:B,2,0) -> IRL | C4: =IFERROR(AVERAGEIFS('Long Format'!F117:F18368,'Long Format'!A117:A18368,A4,'Long Format'!C117:C18368,"Access to electricity, rural (% of rural population)"),"No Data") -> 100 | D4: =IFERROR(RANK(C4,C$2:C$257,0),"") -> 1 | E4: =IF(C4="No Data","No Data",IF(C4>=75,"High",IF(C4>=50,"Medium",IF(C4>=25,"Low","Very Low")))) -> High | F4: =IFERROR(AVERAGEIFS('Long Format'!F33:F18284,'Long Format'!A33:A18284,A4,'Long Format'!C33:C18284,"Trade in services (% of GDP)"),"No Data") -> 121.71304 | G4: =IFERROR(RANK(F4,F$2:F$257,0),"") -> 3 | H4: =IF(F4="No Data","No Data",IF(F4>=50,"High",IF(F4>=25,"Medium",IF(F4>=10,"Low","Very Low")))) -> High
A5: Aruba | B5: =VLOOKUP(A5,'Wide Format'!A:B,2,0) -> ABW | C5: =IFERROR(AVERAGEIFS('Long Format'!F14:F18265,'Long Format'!A14:A18265,A5,'Long Format'!C14:C18265,"Access to electricity, rural (% of rural population)"),"No Data") -> 100 | D5: =IFERROR(RANK(C5,C$2:C$257,0),"") -> 1 | E5: =IF(C5="No Data","No Data",IF(C5>=75,"High",IF(C5>=50,"Medium",IF(C5>=25,"Low","Very Low")))) -> High | F5: =IFERROR(AVERAGEIFS('Long Format'!F3:F18254,'Long Format'!A3:A18254,A5,'Long Format'!C3:C18254,"Trade in services (% of GDP)"),"No Data") -> 99.665337 | G5: =IFERROR(RANK(F5,F$2:F$257,0),"") -> 4 | H5: =IF(F5="No Data","No Data",IF(F5>=50,"High",IF(F5>=25,"Medium",IF(F5>=10,"Low","Very Low")))) -> High
A6: Singapore | B6: =VLOOKUP(A6,'Wide Format'!A:B,2,0) -> SGP | C6: =IFERROR(AVERAGEIFS('Long Format'!F212:F18463,'Long Format'!A212:A18463,A6,'Long Format'!C212:C18463,"Access to electricity, rural (% of rural population)"),"No Data") -> 100 | D6: =IFERROR(RANK(C6,C$2:C$257,0),"") -> 1 | E6: =IF(C6="No Data","No Data",IF(C6>=75,"High",IF(C6>=50,"Medium",IF(C6>=25,"Low","Very Low")))) -> High | F6: =IFERROR(AVERAGEIFS('Long Format'!F58:F18309,'Long Format'!A58:A18309,A6,'Long Format'!C58:C18309,"Trade in services (% of GDP)"),"No Data") -> 97.125778 | G6: =IFERROR(RANK(F6,F$2:F$257,0),"") -> 5 | H6: =IF(F6="No Data","No Data",IF(F6>=50,"High",IF(F6>=25,"Medium",IF(F6>=10,"Low","Very Low")))) -> High
A7: Seychelles | B7: =VLOOKUP(A7,'Wide Format'!A:B,2,0) -> SYC | C7: =IFERROR(AVERAGEIFS('Long Format'!F210:F18461,'Long Format'!A210:A18461,A7,'Long Format'!C210:C18461,"Access to electricity, rural (% of rural population)"),"No Data") -> 95.84375 | D7: =IFERROR(RANK(C7,C$2:C$257,0),"") -> 120 | E7: =IF(C7="No Data","No Data",IF(C7>=75,"High",IF(C7>=50,"Medium",IF(C7>=25,"Low","Very Low")))) -> High | F7: =IFERROR(AVERAGEIFS('Long Format'!F121:F18372,'Long Format'!A121:A18372,A7,'Long Format'!C121:C18372,"Trade in services (% of GDP)"),"No Data") -> 96.545031 | G7: =IFERROR(RANK(F7,F$2:F$257,0),"") -> 6 | H7: =IF(F7="No Data","No Data",IF(F7>=50,"High",IF(F7>=25,"Medium",IF(F7>=10,"Low","Very Low")))) -> High
A8: San Marino | B8: =VLOOKUP(A8,'Wide Format'!A:B,2,0) -> SMR | C8: =IFERROR(AVERAGEIFS('Long Format'!F205:F18456,'Long Format'!A205:A18456,A8,'Long Format'!C205:C18456,"Access to electricity, rural (% of rural population)"),"No Data") -> 100 | D8: =IFERROR(RANK(C8,C$2:C$257,0),"") -> 1 | E8: =IF(C8="No Data","No Data",IF(C8>=75,"High",IF(C8>=50,"Medium",IF(C8>=25,"Low","Very Low")))) -> High | F8: =IFERROR(AVERAGEIFS('Long Format'!F56:F18307,'Long Format'!A56:A18307,A8,'Long Format'!C56:C18307,"Trade in services (% of GDP)"),"No Data") -> 93.280293 | G8: =IFERROR(RANK(F8,F$2:F$257,0),"") -> 7 | H8: =IF(F8="No Data","No Data",IF(F8>=50,"High",IF(F8>=25,"Medium",IF(F8>=10,"Low","Very Low")))) -> High
A9: Andorra | B9: =VLOOKUP(A9,'Wide Format'!A:B,2,0) -> AND | C9: =IFERROR(AVERAGEIFS('Long Format'!F8:F18259,'Long Format'!A8:A18259,A9,'Long Format'!C8:C18259,"Access to electricity, rural (% of rural population)"),"No Data") -> 100 | D9: =IFERROR(RANK(C9,C$2:C$257,0),"") -> 1 | E9: =IF(C9="No Data","No Data",IF(C9>=75,"High",IF(C9>=50,"Medium",IF(C9>=25,"Low","Very Low")))) -> High | F9: =IFERROR(AVERAGEIFS('Long Format'!F2:F18253,'Long Format'!A2:A18253,A9,'Long Format'!C2:C18253,"Trade in services (% of GDP)"),"No Data") -> 92.268316 | G9: =IFERROR(RANK(F9,F$2:F$257,0),"") -> 8 | H9: =IF(F9="No Data","No Data",IF(F9>=50,"High",IF(F9>=25,"Medium",IF(F9>=10,"Low","Very Low")))) -> High
A10: Antigua and Barbuda | B10: =VLOOKUP(A10,'Wide Format'!A:B,2,0) -> ATG | C10: =IFERROR(AVERAGEIFS('Long Format'!F10:F18261,'Long Format'!A10:A18261,A10,'Long Format'!C10:C18261,"Access to electricity, rural (% of rural population)"),"No Data") -> 99.2125 | D10: =IFERROR(RANK(C10,C$2:C$257,0),"") -> 94 | E10: =IF(C10="No Data","No Data",IF(C10>=75,"High",IF(C10>=50,"Medium",IF(C10>=25,"Low","Very Low")))) -> High | F10: =IFERROR(AVERAGEIFS('Long Format'!F95:F18346,'Long Format'!A95:A18346,A10,'Long Format'!C95:C18346,"Trade in services (% of GDP)"),"No Data") -> 87.604985 | G10: =IFERROR(RANK(F10,F$2:F$257,0),"") -> 9 | H10: =IF(F10="No Data","No Data",IF(F10>=50,"High",IF(F10>=25,"Medium",IF(F10>=10,"Low","Very Low")))) -> High
A11: Cayman Islands | B11: =VLOOKUP(A11,'Wide Format'!A:B,2,0) -> CYM | C11: =IFERROR(AVERAGEIFS('Long Format'!F42:F18293,'Long Format'!A42:A18293,A11,'Long Format'!C42:C18293,"Access to electricity, rural (% of rural population)"),"No Data") -> 100 | D11: =IFERROR(RANK(C11,C$2:C$257,0),"") -> 1 | E11: =IF(C11="No Data","No Data",IF(C11>=75,"High",IF(C11>=50,"Medium",IF(C11>=25,"Low","Very Low")))) -> High | F11: =IFERROR(AVERAGEIFS('Long Format'!F12:F18263,'Long Format'!A12:A18263,A11,'Long Format'!C12:C18263,"Trade in services (% of GDP)"),"No Data") -> 86.511674 | G11: =IFERROR(RANK(F11,F$2:F$257,0),"") -> 10 | H11: =IF(F11="No Data","No Data",IF(F11>=50,"High",IF(F11>=25,"Medium",IF(F11>=10,"Low","Very Low")))) -> High
A12: Cyprus | B12: =VLOOKUP(A12,'Wide Format'!A:B,2,0) -> CYP | C12: =IFERROR(AVERAGEIFS('Long Format'!F58:F18309,'Long Format'!A58:A18309,A12,'Long Format'!C58:C18309,"Access to electricity, rural (% of rural population)"),"No Data") -> 100 | D12: =IFERROR(RANK(C12,C$2:C$257,0),"") -> 1 | E12: =IF(C12="No Data","No Data",IF(C12>=75,"High",IF(C12>=50,"Medium",IF(C12>=25,"Low","Very Low")))) -> High | F12: =IFERROR(AVERAGEIFS('Long Format'!F16:F18267,'Long Format'!A16:A18267,A12,'Long Format'!C16:C18267,"Trade in services (% of GDP)"),"No Data") -> 85.355031 | G12: =IFERROR(RANK(F12,F$2:F$257,0),"") -> 11 | H12: =IF(F12="No Data","No Data",IF(F12>=50,"High",IF(F12>=25,"Medium",IF(F12>=10,"Low","Very Low")))) -> High
A13: Macao SAR, China | B13: =VLOOKUP(A13,'Wide Format'!A:B,2,0) -> MAC | C13: =IFERROR(AVERAGEIFS('Long Format'!F148:F18399,'Long Format'!A148:A18399,A13,'Long Format'!C148:C18399,"Access to electricity, rural (% of rural population)"),"No Data") -> 100 | D13: =IFERROR(RANK(C13,C$2:C$257,0),"") -> 1 | E13: =IF(C13="No Data","No Data",IF(C13>=75,"High",IF(C13>=50,"Medium",IF(C13>=25,"Low","Very Low")))) -> High | F13: =IFERROR(AVERAGEIFS('Long Format'!F42:F18293,'Long Format'!A42:A18293,A13,'Long Format'!C42:C18293,"Trade in services (% of GDP)"),"No Data") -> 79.609077 | G13: =IFERROR(RANK(F13,F$2:F$257,0),"") -> 12 | H13: =IF(F13="No Data","No Data",IF(F13>=50,"High",IF(F13>=25,"Medium",IF(F13>=10,"Low","Very Low")))) -> High
A14: Tuvalu | B14: =VLOOKUP(A14,'Wide Format'!A:B,2,0) -> TUV | C14: =IFERROR(AVERAGEIFS('Long Format'!F248:F18499,'Long Format'!A248:A18499,A14,'Long Format'!C248:C18499,"Access to electricity, rural (% of rural population)"),"No Data") -> 96.09375 | D14: =IFERROR(RANK(C14,C$2:C$257,0),"") -> 117 | E14: =IF(C14="No Data","No Data",IF(C14>=75,"High",IF(C14>=50,"Medium",IF(C14>=25,"Low","Very Low")))) -> High | F14: =IFERROR(AVERAGEIFS('Long Format'!F118:F18369,'Long Format'!A118:A18369,A14,'Long Format'!C118:C18369,"Trade in services (% of GDP)"),"No Data") -> 77.755611 | G14: =IFERROR(RANK(F14,F$2:F$257,0),"") -> 13 | H14: =IF(F14="No Data","No Data",IF(F14>=50,"High",IF(F14>=25,"Medium",IF(F14>=10,"Low","Very Low")))) -> High
A15: Sint Maarten (Dutch part) | B15: =VLOOKUP(A15,'Wide Format'!A:B,2,0) -> SXM | C15: =IFERROR(AVERAGEIFS('Long Format'!F213:F18464,'Long Format'!A213:A18464,A15,'Long Format'!C213:C18464,"Access to electricity, rural (% of rural population)"),"No Data") -> 100 | D15: =IFERROR(RANK(C15,C$2:C$257,0),"") -> 1 | E15: =IF(C15="No Data","No Data",IF(C15>=75,"High",IF(C15>=50,"Medium",IF(C15>=25,"Low","Very Low")))) -> High | F15: =IFERROR(AVERAGEIFS('Long Format'!F59:F18310,'Long Format'!A59:A18310,A15,'Long Format'!C59:C18310,"Trade in services (% of GDP)"),"No Data") -> 76.654681 | G15: =IFERROR(RANK(F15,F$2:F$257,0),"") -> 14 | H15: =IF(F15="No Data","No Data",IF(F15>=50,"High",IF(F15>=25,"Medium",IF(F15>=10,"Low","Very Low")))) -> High
A16: Maldives | B16: =VLOOKUP(A16,'Wide Format'!A:B,2,0) -> MDV | C16: =IFERROR(AVERAGEIFS('Long Format'!F152:F18403,'Long Format'!A152:A18403,A16,'Long Format'!C152:C18403,"Access to electricity, rural (% of rural population)"),"No Data") -> 91.74375 | D16: =IFERROR(RANK(C16,C$2:C$257,0),"") -> 134 | E16: =IF(C16="No Data","No Data",IF(C16>=75,"High",IF(C16>=50,"Medium",IF(C16>=25,"Low","Very Low")))) -> High | F16: =IFERROR(AVERAGEIFS('Long Format'!F135:F18386,'Long Format'!A135:A18386,A16,'Long Format'!C135:C18386,"Trade in services (% of GDP)"),"No Data") -> 75.090492 | G16: =IFERROR(RANK(F16,F$2:F$257,0),"") -> 15 | H16: =IF(F16="No Data","No Data",IF(F16>=50,"High",IF(F16>=25,"Medium",IF(F16>=10,"Low","Very Low")))) -> High
A17: St. Kitts and Nevis | B17: =VLOOKUP(A17,'Wide Format'!A:B,2,0) -> KNA | C17: =IFERROR(AVERAGEIFS('Long Format'!F225:F18476,'Long Format'!A225:A18476,A17,'Long Format'!C225:C18476,"Access to electricity, rural (% of rural population)"),"No Data") -> 96.90625 | D17: =IFERROR(RANK(C17,C$2:C$257,0),"") -> 113 | E17: =IF(C17="No Data","No Data",IF(C17>=75,"High",IF(C17>=50,"Medium",IF(C17>=25,"Low","Very Low")))) -> High | F17: =IFERROR(AVERAGEIFS('Long Format'!F114:F18365,'Long Format'!A114:A18365,A17,'Long Format'!C114:C18365,"Trade in services (% of GDP)"),"No Data") -> 70.36268 | G17: =IFERROR(RANK(F17,F$2:F$257,0),"") -> 16 | H17: =IF(F17="No Data","No Data",IF(F17>=50,"High",IF(F17>=25,"Medium",IF(F17>=10,"Low","Very Low")))) -> High
A18: Lebanon | B18: =VLOOKUP(A18,'Wide Format'!A:B,2,0) -> LBN | C18: =IFERROR(AVERAGEIFS('Long Format'!F138:F18389,'Long Format'!A138:A18389,A18,'Long Format'!C138:C18389,"Access to electricity, rural (% of rural population)"),"No Data") -> 98.69375 | D18: =IFERROR(RANK(C18,C$2:C$257,0),"") -> 100 | E18: =IF(C18="No Data","No Data",IF(C18>=75,"High",IF(C18>=50,"Medium",IF(C18>=25,"Low","Very Low")))) -> High | F18: =IFERROR(AVERAGEIFS('Long Format'!F101:F18352,'Long Format'!A101:A18352,A18,'Long Format'!C101:C18352,"Trade in services (% of GDP)"),"No Data") -> 68.955053 | G18: =IFERROR(RANK(F18,F$2:F$257,0),"") -> 17 | H18: =IF(F18="No Data","No Data",IF(F18>=50,"High",IF(F18>=25,"Medium",IF(F18>=10,"Low","Very Low")))) -> High
A19: Curacao | B19: =VLOOKUP(A19,'Wide Format'!A:B,2,0) -> CUW | C19: =IFERROR(AVERAGEIFS('Long Format'!F57:F18308,'Long Format'!A57:A18308,A19,'Long Format'!C57:C18308,"Access to electricity, rural (% of rural population)"),"No Data") -> 100 | D19: =IFERROR(RANK(C19,C$2:C$257,0),"") -> 1 | E19: =IF(C19="No Data","No Data",IF(C19>=75,"High",IF(C19>=50,"Medium",IF(C19>=25,"Low","Very Low")))) -> High | F19: =IFERROR(AVERAGEIFS('Long Format'!F15:F18266,'Long Format'!A15:A18266,A19,'Long Format'!C15:C18266,"Trade in services (% of GDP)"),"No Data") -> 68.717399 | G19: =IFERROR(RANK(F19,F$2:F$257,0),"") -> 18 | H19: =IF(F19="No Data","No Data",IF(F19>=50,"High",IF(F19>=25,"Medium",IF(F19>=10,"Low","Very Low")))) -> High
A20: Nauru | B20: =VLOOKUP(A20,'Wide Format'!A:B,2,0) -> NRU | C20: =IFERROR(AVERAGEIFS('Long Format'!F172:F18423,'Long Format'!A172:A18423,A20,'Long Format'!C172:C18423,"Access to electricity, rural (% of rural population)"),"No Data") -> 100 | D20: =IFERROR(RANK(C20,C$2:C$257,0),"") -> 1 | E20: =IF(C20="No Data","No Data",IF(C20>=75,"High",IF(C20>=50,"Medium",IF(C20>=25,"Low","Very Low")))) -> High | F20: =IFERROR(AVERAGEIFS('Long Format'!F45:F18296,'Long Format'!A45:A18296,A20,'Long Format'!C45:C18296,"Trade in services (% of GDP)"),"No Data") -> 62.644675 | G20: =IFERROR(RANK(F20,F$2:F$257,0),"") -> 19 | H20: =IF(F20="No Data","No Data",IF(F20>=50,"High",IF(F20>=25,"Medium",IF(F20>=10,"Low","Very Low")))) -> High
A21: Turks and Caicos Islands | B21: =VLOOKUP(A21,'Wide Format'!A:B,2,0) -> TCA | C21: =IFERROR(AVERAGEIFS('Long Format'!F247:F18498,'Long Format'!A247:A18498,A21,'Long Format'!C247:C18498,"Access to electricity, rural (% of rural population)"),"No Data") -> 83.1875 | D21: =IFERROR(RANK(C21,C$2:C$257,0),"") -> 151 | E21: =IF(C21="No Data","No Data",IF(C21>=75,"High",IF(C21>=50,"Medium",IF(C21>=25,"Low","Very Low")))) -> High | F21: =IFERROR(AVERAGEIFS('Long Format'!F152:F18403,'Long Format'!A152:A18403,A21,'Long Format'!C152:C18403,"Trade in services (% of GDP)"),"No Data") -> 61.890459 | G21: =IFERROR(RANK(F21,F$2:F$257,0),"") -> 20 | H21: =IF(F21="No Data","No Data",IF(F21>=50,"High",IF(F21>=25,"Medium",IF(F21>=10,"Low","Very Low")))) -> High
A22: St. Lucia | B22: =VLOOKUP(A22,'Wide Format'!A:B,2,0) -> LCA | C22: =IFERROR(AVERAGEIFS('Long Format'!F226:F18477,'Long Format'!A226:A18477,A22,'Long Format'!C226:C18477,"Access to electricity, rural (% of rural population)"),"No Data") -> 93.125 | D22: =IFERROR(RANK(C22,C$2:C$257,0),"") -> 125 | E22: =IF(C22="No Data","No Data",IF(C22>=75,"High",IF(C22>=50,"Medium",IF(C22>=25,"Low","Very Low")))) -> High | F22: =IFERROR(AVERAGEIFS('Long Format'!F126:F18377,'Long Format'!A126:A18377,A22,'Long Format'!C126:C18377,"Trade in services (% of GDP)"),"No Data") -> 60.705632 | G22: =IFERROR(RANK(F22,F$2:F$257,0),"") -> 21 | H22: =IF(F22="No Data","No Data",IF(F22>=50,"High",IF(F22>=25,"Medium",IF(F22>=10,"Low","Very Low")))) -> High
A23: Grenada | B23: =VLOOKUP(A23,'Wide Format'!A:B,2,0) -> GRD | C23: =IFERROR(AVERAGEIFS('Long Format'!F95:F18346,'Long Format'!A95:A18346,A23,'Long Format'!C95:C18346,"Access to electricity, rural (% of rural population)"),"No Data") -> No Data | D23: =IFERROR(RANK(C23,C$2:C$257,0),"") | E23: =IF(C23="No Data","No Data",IF(C23>=75,"High",IF(C23>=50,"Medium",IF(C23>=25,"Low","Very Low")))) -> No Data | F23: =IFERROR(AVERAGEIFS('Long Format'!F257:F18508,'Long Format'!A257:A18508,A23,'Long Format'!C257:C18508,"Trade in services (% of GDP)"),"No Data") -> 59.026501 | G23: =IFERROR(RANK(F23,F$2:F$257,0),"") -> 22 | H23: =IF(F23="No Data","No Data",IF(F23>=50,"High",IF(F23>=25,"Medium",IF(F23>=10,"Low","Very Low")))) -> High
A24: Other small states | B24: =VLOOKUP(A24,'Wide Format'!A:B,2,0) -> OSS | C24: =IFERROR(AVERAGEIFS('Long Format'!F186:F18437,'Long Format'!A186:A18437,A24,'Long Format'!C186:C18437,"Access to electricity, rural (% of rural population)"),"No Data") -> 71.467218 | D24: =IFERROR(RANK(C24,C$2:C$257,0),"") -> 173 | E24: =IF(C24="No Data","No Data",IF(C24>=75,"High",IF(C24>=50,"Medium",IF(C24>=25,"Low","Very Low")))) -> Medium | F24: =IFERROR(AVERAGEIFS('Long Format'!F174:F18425,'Long Format'!A174:A18425,A24,'Long Format'!C174:C18425,"Trade in services (% of GDP)"),"No Data") -> 55.017908 | G24: =IFERROR(RANK(F24,F$2:F$257,0),"") -> 23 | H24: =IF(F24="No Data","No Data",IF(F24>=50,"High",IF(F24>=25,"Medium",IF(F24>=10,"Low","Very Low")))) -> High
A25: United Arab Emirates | B25: =VLOOKUP(A25,'Wide Format'!A:B,2,0) -> ARE | C25: =IFERROR(AVERAGEIFS('Long Format'!F251:F18502,'Long Format'!A251:A18502,A25,'Long Format'!C251:C18502,"Access to electricity, rural (% of rural population)"),"No Data") -> 100 | D25: =IFERROR(RANK(C25,C$2:C$257,0),"") -> 1 | E25: =IF(C25="No Data","No Data",IF(C25>=75,"High",IF(C25>=50,"Medium",IF(C25>=25,"Low","Very Low")))) -> High | F25: =IFERROR(AVERAGEIFS('Long Format'!F66:F18317,'Long Format'!A66:A18317,A25,'Long Format'!C66:C18317,"Trade in services (% of GDP)"),"No Data") -> 53.725812 | G25: =IFERROR(RANK(F25,F$2:F$257,0),"") -> 24 | H25: =IF(F25="No Data","No Data",IF(F25>=50,"High",IF(F25>=25,"Medium",IF(F25>=10,"Low","Very Low")))) -> High
A26: Dominica | B26: =VLOOKUP(A26,'Wide Format'!A:B,2,0) -> DMA | C26: =IFERROR(AVERAGEIFS('Long Format'!F62:F18313,'Long Format'!A62:A18313,A26,'Long Format'!C62:C18313,"Access to electricity, rural (% of rural population)"),"No Data") -> 100 | D26: =IFERROR(RANK(C26,C$2:C$257,0),"") -> 1 | E26: =IF(C26="No Data","No Data",IF(C26>=75,"High",IF(C26>=50,"Medium",IF(C26>=25,"Low","Very Low")))) -> High | F26: =IFERROR(AVERAGEIFS('Long Format'!F19:F18270,'Long Format'!A19:A18270,A26,'Long Format'!C19:C18270,"Trade in services (% of GDP)"),"No Data") -> 52.539618 | G26: =IFERROR(RANK(F26,F$2:F$257,0),"") -> 25 | H26: =IF(F26="No Data","No Data",IF(F26>=50,"High",IF(F26>=25,"Medium",IF(F26>=10,"Low","Very Low")))) -> High
A27: Vanuatu | B27: =VLOOKUP(A27,'Wide Format'!A:B,2,0) -> VUT | C27: =IFERROR(AVERAGEIFS('Long Format'!F257:F18508,'Long Format'!A257:A18508,A27,'Long Format'!C257:C18508,"Access to electricity, rural (% of rural population)"),"No Data") -> 31.75 | D27: =IFERROR(RANK(C27,C$2:C$257,0),"") -> 206 | E27: =IF(C27="No Data","No Data",IF(C27>=75,"High",IF(C27>=50,"Medium",IF(C27>=25,"Low","Very Low")))) -> Low | F27: =IFERROR(AVERAGEIFS('Long Format'!F207:F18458,'Long Format'!A207:A18458,A27,'Long Format'!C207:C18458,"Trade in services (% of GDP)"),"No Data") -> 52.208798 | G27: =IFERROR(RANK(F27,F$2:F$257,0),"") -> 26 | H27: =IF(F27="No Data","No Data",IF(F27>=50,"High",IF(F27>=25,"Medium",IF(F27>=10,"Low","Very Low")))) -> High
A28: Liberia | B28: =VLOOKUP(A28,'Wide Format'!A:B,2,0) -> LBR | C28: =IFERROR(AVERAGEIFS('Long Format'!F140:F18391,'Long Format'!A140:A18391,A28,'Long Format'!C140:C18391,"Access to electricity, rural (% of rural population)"),"No Data") -> 9.1142857 | D28: =IFERROR(RANK(C28,C$2:C$257,0),"") -> 240 | E28: =IF(C28="No Data","No Data",IF(C28>=75,"High",IF(C28>=50,"Medium",IF(C28>=25,"Low","Very Low")))) -> Very Low | F28: =IFERROR(AVERAGEIFS('Long Format'!F241:F18492,'Long Format'!A241:A18492,A28,'Long Format'!C241:C18492,"Trade in services (% of GDP)"),"No Data") -> 50.531563 | G28: =IFERROR(RANK(F28,F$2:F$257,0),"") -> 27 | H28: =IF(F28="No Data","No Data",IF(F28>=50,"High",IF(F28>=25,"Medium",IF(F28>=10,"Low","Very Low")))) -> High
A29: Palau | B29: =VLOOKUP(A29,'Wide Format'!A:B,2,0) -> PLW | C29: =IFERROR(AVERAGEIFS('Long Format'!F189:F18440,'Long Format'!A189:A18440,A29,'Long Format'!C189:C18440,"Access to electricity, rural (% of rural population)"),"No Data") -> 97.825 | D29: =IFERROR(RANK(C29,C$2:C$257,0),"") -> 109 | E29: =IF(C29="No Data","No Data",IF(C29>=75,"High",IF(C29>=50,"Medium",IF(C29>=25,"Low","Very Low")))) -> High | F29: =IFERROR(AVERAGEIFS('Long Format'!F110:F18361,'Long Format'!A110:A18361,A29,'Long Format'!C110:C18361,"Trade in services (% of GDP)"),"No Data") -> 50.112097 | G29: =IFERROR(RANK(F29,F$2:F$257,0),"") -> 28 | H29: =IF(F29="No Data","No Data",IF(F29>=50,"High",IF(F29>=25,"Medium",IF(F29>=10,"Low","Very Low")))) -> High
